<?xml version="1.0"?>
<robot name="collision_robot">
  
  <!-- Base Link -->
  <link name="base_link">
    <visual>
      <geometry>
        <box size="0.6 0.4 0.2"/>
      </geometry>
      <material name="purple">
        <color rgba="0.8 0.2 0.8 1.0"/>
      </material>
    </visual>
    <collision>
      <geometry>
        <box size="0.6 0.4 0.2"/>
      </geometry>
    </collision>
  </link>
  
  <!-- Arm Link -->
  <link name="arm_link">
    <visual>
      <geometry>
        <cylinder radius="0.05" length="0.6"/>
      </geometry>
      <material name="cyan">
        <color rgba="0.2 0.8 0.8 1.0"/>
      </material>
      <origin rpy="0 0 0" xyz="0 0 0.3"/>
    </visual>
    <collision>
      <geometry>
        <cylinder radius="0.05" length="0.6"/>
      </geometry>
      <origin rpy="0 0 0" xyz="0 0 0.3"/>
    </collision>
  </link>
  
  <!-- End Effector Link -->
  <link name="end_effector">
    <visual>
      <geometry>
        <sphere radius="0.08"/>
      </geometry>
      <material name="magenta">
        <color rgba="1.0 0.2 1.0 1.0"/>
      </material>
    </visual>
    <collision>
      <geometry>
        <sphere radius="0.08"/>
      </geometry>
    </collision>
  </link>
  
  <!-- Joints -->
  <joint name="base_to_arm" type="revolute">
    <parent link="base_link"/>
    <child link="arm_link"/>
    <origin xyz="0.25 0 0.10" rpy="0 0 0"/>
    <axis xyz="0 1 0"/>
    <limit lower="-1.57" upper="1.57" effort="100" velocity="1.0"/>
  </joint>
  
  <joint name="arm_to_end" type="revolute">
    <parent link="arm_link"/>
    <child link="end_effector"/>
    <origin xyz="0 0 0.6" rpy="0 0 0"/>
    <axis xyz="1 0 0"/>
    <limit lower="-0.78" upper="0.78" effort="50" velocity="1.0"/>
  </joint>
  
</robot>