<?xml version="1.0"?>
<robot name="mobile_robot">
  
  <!-- Main body -->
  <link name="base_link">
    <visual>
      <geometry>
        <box size="0.8 0.5 0.2"/>
      </geometry>
      <material name="gray">
        <color rgba="0.5 0.5 0.5 1.0"/>
      </material>
    </visual>
    <collision>
      <geometry>
        <box size="0.8 0.5 0.2"/>
      </geometry>
    </collision>
  </link>
  
  <!-- Left wheel -->
  <link name="left_wheel">
    <visual>
      <geometry>
        <cylinder radius="0.15" length="0.05"/>
      </geometry>
      <material name="black">
        <color rgba="0.1 0.1 0.1 1.0"/>
      </material>
    </visual>
  </link>
  
  <!-- Right wheel -->
  <link name="right_wheel">
    <visual>
      <geometry>
        <cylinder radius="0.15" length="0.05"/>
      </geometry>
      <material name="black">
        <color rgba="0.1 0.1 0.1 1.0"/>
      </material>
    </visual>
  </link>
  
  <!-- Sensor mast -->
  <link name="sensor_mast">
    <visual>
      <geometry>
        <cylinder radius="0.03" length="0.4"/>
      </geometry>
      <material name="blue">
        <color rgba="0.0 0.0 1.0 1.0"/>
      </material>
    </visual>
  </link>
  
  <!-- Camera/Sensor -->
  <link name="camera">
    <visual>
      <geometry>
        <box size="0.1 0.08 0.05"/>
      </geometry>
      <material name="green">
        <color rgba="0.0 1.0 0.0 1.0"/>
      </material>
    </visual>
  </link>
  
  <!-- Wheel joints -->
  <joint name="base_to_left_wheel" type="continuous">
    <parent link="base_link"/>
    <child link="left_wheel"/>
    <origin xyz="0.2 0.3 -0.1" rpy="1.5708 0 0"/>
    <axis xyz="0 0 1"/>
  </joint>
  
  <joint name="base_to_right_wheel" type="continuous">
    <parent link="base_link"/>
    <child link="right_wheel"/>
    <origin xyz="0.2 -0.3 -0.1" rpy="1.5708 0 0"/>
    <axis xyz="0 0 1"/>
  </joint>
  
  <!-- Sensor mast joint -->
  <joint name="base_to_mast" type="revolute">
    <parent link="base_link"/>
    <child link="sensor_mast"/>
    <origin xyz="-0.2 0 0.1" rpy="0 0 0"/>
    <axis xyz="0 0 1"/>
    <limit lower="-3.14159" upper="3.14159" effort="10" velocity="2.0"/>
  </joint>
  
  <!-- Camera joint -->
  <joint name="mast_to_camera" type="revolute">
    <parent link="sensor_mast"/>
    <child link="camera"/>
    <origin xyz="0 0 0.22" rpy="0 0 0"/>
    <axis xyz="0 1 0"/>
    <limit lower="-1.57" upper="1.57" effort="5" velocity="1.0"/>
  </joint>
  
</robot>